Workbook
Name avgint: '[1]LBO Model'!$K$37
Name fincase: '[1]LBO Model'!$K$6
Name tax: '[1]LBO Model'!$K$16

Sheet LBO Model Base Case
A1: Luke Buddie, Gennaro Di Mauro, Peter Spira, Caden Carney
B2: Step 1: Outline everything you know
B3: Williams-Sonoma, Inc., LBO: Let’s Get Cooking
B4: Assumptions
B6: 2024 EBITDA | D6: ='Ex 10 Projections'!E18 -> 1438.43 | E6: Exhibit 10 | H6: Exit multiple | I6: =D12 -> 7.5
B7: SOFR | D7: 0.03 | H7: Number of shares outstanding (in millions) | I7: ='Ex 11 Comps'!I16 -> 64.2 | J7: Exhibit 11
B8: Tax rate | D8: 0.23 | E8: Exhibit 10 | H8: Current enterprise value | I8: =('Ex 11 Comps'!I16*'Ex 11 Comps'!J16)+'Ex 11 Comps'!K16 -> 8758.648 | J8: Equity Value + Debt Value
B9: Opening Balance Cash | D9: 0 | E9: Exhibit 9 - Case
B11: Financing Package | E11: Amount | F11: Cash Interest | G11: PIK | H11: Target Leverage (between 4-6) | J11: SOFR +
B12: Purchase multiple | D12: =SUM(D13:D16) -> 7.5 | E12: =D6*D12 -> 10788.225
B13: Term A | D13: 2.5 | E13: =D13*$D$6 -> 3596.075 | F13: =D7+J13 -> 0.055 | H13: =(E13+E14)/E29 -> 3.5 | J13: 0.025
B14: Term B | D14: 1 | E14: =D14*$D$6 -> 1438.43 | F14: =D7+J14 -> 0.075 | J14: 0.045
B15: Mezzanine (Cavalier Capital) | D15: 2 | E15: =D15*$D$6 -> 2876.86 | F15: 0.11 | G15: 0.02 | J15: Minimum Priciple
B16: Equity investment (Jeffereson Capital Management) | D16: 2 | E16: =E12-E13-E14-E15 -> 2876.86 | J16: 0.05
B19: Step 2: How/Who are you going to pay down your debt with your free cash flow?
B20: Williams-Sonoma, Inc., LBO: Let’s Get Cooking
B21: Debt-Repayment Schedule | K21: Target Leverage
K22: Debt/EBITDA: 4-6x
D23: 2023 | E23: 2024 | F23: 2025 | G23: 2026 | H23: 2027 | I23: 2028
B24: ='Ex 10 Projections'!B11 -> Total revenue | D24: ='Ex 10 Projections'!D11 -> 8674.42 | E24: ='Ex 10 Projections'!E11 -> 8471 | F24: ='Ex 10 Projections'!F11 -> 8553 | G24: ='Ex 10 Projections'!G11 -> 8862.29 | H24: ='Ex 10 Projections'!H11 -> 9181.33 | I24: ='Ex 10 Projections'!I11 -> 9582.61
B25: ='Ex 10 Projections'!B12 -> Cost of goods sold | D25: ='Ex 10 Projections'!D12 -> 4996.68 | E25: ='Ex 10 Projections'!E12 -> 5067.8 | F25: ='Ex 10 Projections'!F12 -> 5082.1 | G25: ='Ex 10 Projections'!G12 -> 5241.16 | H25: ='Ex 10 Projections'!H12 -> 5407.8 | I25: ='Ex 10 Projections'!I12 -> 5605.83
B26: ='Ex 10 Projections'!B13 -> Gross profit | D26: =D24-D25 -> 3677.74 | E26: =E24-E25 -> 3403.2 | F26: =F24-F25 -> 3470.9 | G26: =G24-G25 -> 3621.13 | H26: =H24-H25 -> 3773.53 | I26: =I24-I25 -> 3976.78
B27: ='Ex 10 Projections'!B14 -> Selling, general, and administrative expenses | D27: ='Ex 10 Projections'!D14 -> 2179.31 | E27: ='Ex 10 Projections'!E14 -> 2189.6 | F27: ='Ex 10 Projections'!F14 -> 2223.7 | G27: ='Ex 10 Projections'!G14 -> 2395.05 | H27: ='Ex 10 Projections'!H14 -> 2313.43 | I27: ='Ex 10 Projections'!I14 -> 2443.78
B28: ='Ex 10 Projections'!B17 -> Depreciation and amortization | D28: ='Ex 10 Projections'!D17 -> 214.2 | E28: ='Ex 10 Projections'!E17 -> 224.83 | F28: ='Ex 10 Projections'!F17 -> 233.48 | G28: ='Ex 10 Projections'!G17 -> 250.75 | H28: ='Ex 10 Projections'!H17 -> 252.51 | I28: ='Ex 10 Projections'!I17 -> 263.87
B29: ='Ex 10 Projections'!B18 -> EBITDA | D29: =(D26-D27+D28) -> 1712.63 | E29: =(E26-E27+E28) -> 1438.43 | F29: =(F26-F27+F28) -> 1480.68 | G29: =(G26-G27+G28) -> 1476.83 | H29: =(H26-H27+H28) -> 1712.61 | I29: =(I26-I27+I28) -> 1796.87
B30: Haircut to EBITDA (difference from expected EBITDA vs. realitstic) | C30: 0 | D30: =D29*(1+$C$30) -> 1712.63 | E30: =E29*(1+$C$30) -> 1438.43 | F30: =F29*(1+$C$30) -> 1480.68 | G30: =G29*(1+$C$30) -> 1476.83 | H30: =H29*(1+$C$30) -> 1712.61 | I30: =I29*(1+$C$30) -> 1796.87
B32: ='Ex 10 Projections'!B15 -> Operating income (EBIT) | D32: =D30-D28 -> 1498.43 | E32: =E30-E28 -> 1213.6 | F32: =F30-F28 -> 1247.2 | G32: =G30-G28 -> 1226.08 | H32: =H30-H28 -> 1460.1 | I32: =I30-I28 -> 1533
B33: ='Ex 10 Projections'!B22 -> CAPEX | D33: ='Ex 10 Projections'!D22 -> 354.1 | E33: ='Ex 10 Projections'!E22 -> 249.4 | F33: ='Ex 10 Projections'!F22 -> 262.31 | G33: ='Ex 10 Projections'!G22 -> 263.81 | H33: ='Ex 10 Projections'!H22 -> 320.49 | I33: ='Ex 10 Projections'!I22 -> 345.07
B34: ='Ex 10 Projections'!B23 -> Change in net working capital (NWC) | D34: ='Ex 10 Projections'!D23 -> -152.6 | E34: ='Ex 10 Projections'!E23 -> 227.87 | F34: ='Ex 10 Projections'!F23 -> 6.07 | G34: ='Ex 10 Projections'!G23 -> 22.91 | H34: ='Ex 10 Projections'!H23 -> 23.63 | I34: ='Ex 10 Projections'!I23 -> 29.72
B36: FCF | E36: =E32*(1-$D$8)+E28-E33-E34 -> 682.032 | F36: =F32*(1-$D$8)+F28-F33-F34 -> 925.444 | G36: =G32*(1-$D$8)+G28-G33-G34 -> 908.1116 | H36: =H32*(1-$D$8)+H28-H33-H34 -> 1032.667 | I36: =I32*(1-$D$8)+I28-I33-I34 -> 1069.49
B37: Beginning Balance | E37: =E13 -> 3596.075 | F37: =E37-E38 -> 3416.2713 | G37: =F37-F38 -> 3236.4675 | H37: =G37-G38 -> 3056.6638 | I37: =H37-H38 -> 2876.86
B38: Term A Principal | E38: =$J$16*$E$37 -> 179.80375 | F38: =$J$16*$E$37 -> 179.80375 | G38: =$J$16*$E$37 -> 179.80375 | H38: =$J$16*$E$37 -> 179.80375 | I38: =$J$16*$E$37 -> 179.80375
B39: Interest | E39: =$F$13*E37 -> 197.78413 | F39: =$F$13*F37 -> 187.89492 | G39: =$F$13*G37 -> 178.00571 | H39: =$F$13*H37 -> 168.11651 | I39: =$F$13*I37 -> 158.2273
B41: Total Debt | E41: =E38+E39 -> 377.58788 | F41: =F38+F39 -> 367.69867 | G41: =G38+G39 -> 357.80946 | H41: =H38+H39 -> 347.92026 | I41: =I38+I39 -> 338.03105
B42: Tax shield | E42: =E39*$D$8 -> 45.490349 | F42: =F39*$D$8 -> 43.215831 | G42: =G39*$D$8 -> 40.941314 | H42: =H39*$D$8 -> 38.666796 | I42: =I39*$D$8 -> 36.392279
B43: Excess Cash Flow | E43: =E36-E41+E42 -> 349.93447 | F43: =F36-F41+F42 -> 600.96116 | G43: =G36-G41+G42 -> 591.24345 | H43: =H36-H41+H42 -> 723.41354 | I43: =I36-I41+I42 -> 767.85123
B44: FCC | E44: =(E41+E43)/E41 -> 1.926763 | F44: =(F41+F43)/F41 -> 2.6343849 | G44: =(G41+G43)/G41 -> 2.6523975 | H44: =(H41+H43)/H41 -> 3.079251 | I44: =(I41+I43)/I41 -> 3.2715405
B46: Term B
B47: FCF | E47: =E43 -> 349.93447 | F47: =F43 -> 600.96116 | G47: =G43 -> 591.24345 | H47: =H43 -> 723.41354 | I47: =I43 -> 767.85123
B48: No principal
...

Sheet LBO Model- OPTIMAL CASE
A1: Luke Buddie, Gennaro Di Mauro, Peter Spira, Caden Carney
B2: Step 1: Outline everything you know
B3: Williams-Sonoma, Inc., LBO: Let’s Get Cooking
B4: Assumptions
B6: 2024 EBITDA | D6: ='Ex 10 Projections'!E18 -> 1438.43 | E6: Exhibit 10 | H6: Exit multiple | I6: =D12 -> 7.5 | L6: Term A | M6: =E13 -> 4315.29
B7: SOFR | D7: 0.03 | H7: Number of shares outstanding (in millions) | I7: ='Ex 11 Comps'!I16 -> 64.2 | J7: Exhibit 11 | L7: Term B | M7: =E14 -> 2157.645
B8: Tax rate | D8: 0.23 | E8: Exhibit 10 | H8: Current enterprise value | I8: =('Ex 11 Comps'!I16*'Ex 11 Comps'!J16)+'Ex 11 Comps'!K16 -> 8758.648 | J8: Equity Value + Debt Value | L8: Sub Debt | M8: =E15 -> 1438.43
B9: Opening Balance Cash | D9: 0 | E9: Exhibit 9 - Case | L9: Equity | M9: =E16 -> 2876.86
L10: Bid | M10: =SUM(M6:M9) -> 10788.225
B11: Financing Package | E11: Amount | F11: Cash Interest | G11: PIK | J11: SOFR +
B12: Purchase multiple | D12: =SUM(D13:D16) -> 7.5 | E12: =D6*D12 -> 10788.225 | L12: EBITDA | M12: =E30 -> 1438.43
B13: Term A | D13: 3 | E13: =D13*$D$6 -> 4315.29 | F13: =D7+J13 -> 0.055 | J13: 0.025 | L13: Multiple: | M13: =M10/M12 -> 7.5
B14: Term B | D14: 1.5 | E14: =D14*$D$6 -> 2157.645 | F14: =D7+J14 -> 0.075 | J14: 0.045
B15: Mezzanine (Cavalier Capital) | D15: 1 | E15: =D15*$D$6 -> 1438.43 | F15: 0.11 | G15: 0.02 | J15: Minimum Priciple
B16: Equity investment (Jeffereson Capital Management) | D16: 2 | E16: =E12-E13-E14-E15 -> 2876.86 | J16: 0.05
B19: Step 2: How/Who are you going to pay down your debt with your free cash flow?
B20: Williams-Sonoma, Inc., LBO: Let’s Get Cooking
B21: Debt-Repayment Schedule | K21: Target Leverage
K22: Debt/EBITDA: 4-6x
D23: 2023 | E23: 2024 | F23: 2025 | G23: 2026 | H23: 2027 | I23: 2028
B24: ='Ex 10 Projections'!B11 -> Total revenue | D24: ='Ex 10 Projections'!D11 -> 8674.42 | E24: ='Ex 10 Projections'!E11 -> 8471 | F24: ='Ex 10 Projections'!F11 -> 8553 | G24: ='Ex 10 Projections'!G11 -> 8862.29 | H24: ='Ex 10 Projections'!H11 -> 9181.33 | I24: ='Ex 10 Projections'!I11 -> 9582.61
B25: ='Ex 10 Projections'!B12 -> Cost of goods sold | D25: ='Ex 10 Projections'!D12 -> 4996.68 | E25: ='Ex 10 Projections'!E12 -> 5067.8 | F25: ='Ex 10 Projections'!F12 -> 5082.1 | G25: ='Ex 10 Projections'!G12 -> 5241.16 | H25: ='Ex 10 Projections'!H12 -> 5407.8 | I25: ='Ex 10 Projections'!I12 -> 5605.83
B26: ='Ex 10 Projections'!B13 -> Gross profit | D26: =D24-D25 -> 3677.74 | E26: =E24-E25 -> 3403.2 | F26: =F24-F25 -> 3470.9 | G26: =G24-G25 -> 3621.13 | H26: =H24-H25 -> 3773.53 | I26: =I24-I25 -> 3976.78
B27: ='Ex 10 Projections'!B14 -> Selling, general, and administrative expenses | D27: ='Ex 10 Projections'!D14 -> 2179.31 | E27: ='Ex 10 Projections'!E14 -> 2189.6 | F27: ='Ex 10 Projections'!F14 -> 2223.7 | G27: ='Ex 10 Projections'!G14 -> 2395.05 | H27: ='Ex 10 Projections'!H14 -> 2313.43 | I27: ='Ex 10 Projections'!I14 -> 2443.78
B28: ='Ex 10 Projections'!B17 -> Depreciation and amortization | D28: ='Ex 10 Projections'!D17 -> 214.2 | E28: ='Ex 10 Projections'!E17 -> 224.83 | F28: ='Ex 10 Projections'!F17 -> 233.48 | G28: ='Ex 10 Projections'!G17 -> 250.75 | H28: ='Ex 10 Projections'!H17 -> 252.51 | I28: ='Ex 10 Projections'!I17 -> 263.87
B29: ='Ex 10 Projections'!B18 -> EBITDA | D29: =(D26-D27+D28) -> 1712.63 | E29: =(E26-E27+E28) -> 1438.43 | F29: =(F26-F27+F28) -> 1480.68 | G29: =(G26-G27+G28) -> 1476.83 | H29: =(H26-H27+H28) -> 1712.61 | I29: =(I26-I27+I28) -> 1796.87
B30: Haircut to EBITDA (difference from expected EBITDA vs. realitstic) | C30: 0 | D30: =D29*(1+$C$30) -> 1712.63 | E30: =E29*(1+$C$30) -> 1438.43 | F30: =F29*(1+$C$30) -> 1480.68 | G30: =G29*(1+$C$30) -> 1476.83 | H30: =H29*(1+$C$30) -> 1712.61 | I30: =I29*(1+$C$30) -> 1796.87
B32: ='Ex 10 Projections'!B15 -> Operating income (EBIT) | D32: =D30-D28 -> 1498.43 | E32: =E30-E28 -> 1213.6 | F32: =F30-F28 -> 1247.2 | G32: =G30-G28 -> 1226.08 | H32: =H30-H28 -> 1460.1 | I32: =I30-I28 -> 1533
B33: ='Ex 10 Projections'!B22 -> CAPEX | D33: ='Ex 10 Projections'!D22 -> 354.1 | E33: ='Ex 10 Projections'!E22 -> 249.4 | F33: ='Ex 10 Projections'!F22 -> 262.31 | G33: ='Ex 10 Projections'!G22 -> 263.81 | H33: ='Ex 10 Projections'!H22 -> 320.49 | I33: ='Ex 10 Projections'!I22 -> 345.07
B34: ='Ex 10 Projections'!B23 -> Change in net working capital (NWC) | D34: ='Ex 10 Projections'!D23 -> -152.6 | E34: ='Ex 10 Projections'!E23 -> 227.87 | F34: ='Ex 10 Projections'!F23 -> 6.07 | G34: ='Ex 10 Projections'!G23 -> 22.91 | H34: ='Ex 10 Projections'!H23 -> 23.63 | I34: ='Ex 10 Projections'!I23 -> 29.72
B36: FCF | E36: =E32*(1-$D$8)+E28-E33-E34 -> 682.032 | F36: =F32*(1-$D$8)+F28-F33-F34 -> 925.444 | G36: =G32*(1-$D$8)+G28-G33-G34 -> 908.1116 | H36: =H32*(1-$D$8)+H28-H33-H34 -> 1032.667 | I36: =I32*(1-$D$8)+I28-I33-I34 -> 1069.49
B37: Beginning Balance | E37: =E13 -> 4315.29 | F37: =E37-E38 -> 4099.5255 | G37: =F37-F38 -> 3883.761 | H37: =G37-G38 -> 3667.9965 | I37: =H37-H38 -> 3452.232
B38: Term A Principal | E38: =$J$16*$E$37 -> 215.7645 | F38: =$J$16*$E$37 -> 215.7645 | G38: =$J$16*$E$37 -> 215.7645 | H38: =$J$16*$E$37 -> 215.7645 | I38: =$J$16*$E$37 -> 215.7645
B39: Interest | E39: =$F$13*E37 -> 237.34095 | F39: =$F$13*F37 -> 225.4739 | G39: =$F$13*G37 -> 213.60685 | H39: =$F$13*H37 -> 201.73981 | I39: =$F$13*I37 -> 189.87276
B41: Total Debt | E41: =E38+E39 -> 453.10545 | F41: =F38+F39 -> 441.2384 | G41: =G38+G39 -> 429.37135 | H41: =H38+H39 -> 417.50431 | I41: =I38+I39 -> 405.63726
B42: Tax shield | E42: =E39*$D$8 -> 54.588419 | F42: =F39*$D$8 -> 51.858998 | G42: =G39*$D$8 -> 49.129577 | H42: =H39*$D$8 -> 46.400156 | I42: =I39*$D$8 -> 43.670735
B43: Excess Cash Flow | E43: =E36-E41+E42 -> 283.51497 | F43: =F36-F41+F42 -> 536.0646 | G43: =G36-G41+G42 -> 527.86982 | H43: =H36-H41+H42 -> 661.56285 | I43: =I36-I41+I42 -> 707.52347
B44: FCC | E44: =(E41+E43)/E41 -> 1.6257152 | F44: =(F41+F43)/F41 -> 2.2149092 | G44: =(G41+G43)/G41 -> 2.2294016 | H44: =(H41+H43)/H41 -> 2.5845653 | I44: =(I41+I43)/I41 -> 2.744227
B46: Term B
B47: FCF | E47: =E43 -> 283.51497 | F47: =F43 -> 536.0646 | G47: =G43 -> 527.86982 | H47: =H43 -> 661.56285 | I47: =I43 -> 707.52347
...

Sheet LBO Model- 4x Debt A
A1: Luke Buddie, Gennaro Di Mauro, Peter Spira, Caden Carney
B2: Step 1: Outline everything you know
B3: Williams-Sonoma, Inc., LBO: Let’s Get Cooking
B4: Assumptions
B6: 2024 EBITDA | D6: ='Ex 10 Projections'!E18 -> 1438.43 | E6: Exhibit 10 | H6: Exit multiple | I6: =D12 -> 9
B7: SOFR | D7: 0.03 | H7: Number of shares outstanding (in millions) | I7: ='Ex 11 Comps'!I16 -> 64.2 | J7: Exhibit 11
B8: Tax rate | D8: 0.23 | E8: Exhibit 10 | H8: Current enterprise value | I8: =('Ex 11 Comps'!I16*'Ex 11 Comps'!J16)+'Ex 11 Comps'!K16 -> 8758.648 | J8: Equity Value + Debt Value
B9: Opening Balance Cash | D9: 0 | E9: Exhibit 9 - Case
B11: Financing Package | E11: Amount | F11: Cash Interest | G11: PIK | H11: Target L:everage | J11: SOFR +
B12: Purchase multiple | D12: =SUM(D13:D16) -> 9 | E12: =D6*D12 -> 12945.87
B13: Term A | D13: 4 | E13: =D13*$D$6 -> 5753.72 | F13: =D7+J13 -> 0.055 | H13: =(E13+E14)/E29 -> 5 | J13: 0.025
B14: Term B | D14: 1 | E14: =D14*$D$6 -> 1438.43 | F14: =D7+J14 -> 0.075 | J14: 0.045
B15: Mezzanine (Cavalier Capital) | D15: 2 | E15: =D15*$D$6 -> 2876.86 | F15: 0.11 | G15: 0.02 | J15: Minimum Priciple
B16: Equity investment (Jeffereson Capital Management) | D16: 2 | E16: =E12-E13-E14-E15 -> 2876.86 | J16: 0.05
B19: Step 2: How/Who are you going to pay down your debt with your free cash flow?
B20: Williams-Sonoma, Inc., LBO: Let’s Get Cooking
B21: Debt-Repayment Schedule | K21: Target Leverage
K22: Debt/EBITDA: 4-6x
D23: 2023 | E23: 2024 | F23: 2025 | G23: 2026 | H23: 2027 | I23: 2028
B24: ='Ex 10 Projections'!B11 -> Total revenue | D24: ='Ex 10 Projections'!D11 -> 8674.42 | E24: ='Ex 10 Projections'!E11 -> 8471 | F24: ='Ex 10 Projections'!F11 -> 8553 | G24: ='Ex 10 Projections'!G11 -> 8862.29 | H24: ='Ex 10 Projections'!H11 -> 9181.33 | I24: ='Ex 10 Projections'!I11 -> 9582.61
B25: ='Ex 10 Projections'!B12 -> Cost of goods sold | D25: ='Ex 10 Projections'!D12 -> 4996.68 | E25: ='Ex 10 Projections'!E12 -> 5067.8 | F25: ='Ex 10 Projections'!F12 -> 5082.1 | G25: ='Ex 10 Projections'!G12 -> 5241.16 | H25: ='Ex 10 Projections'!H12 -> 5407.8 | I25: ='Ex 10 Projections'!I12 -> 5605.83
B26: ='Ex 10 Projections'!B13 -> Gross profit | D26: =D24-D25 -> 3677.74 | E26: =E24-E25 -> 3403.2 | F26: =F24-F25 -> 3470.9 | G26: =G24-G25 -> 3621.13 | H26: =H24-H25 -> 3773.53 | I26: =I24-I25 -> 3976.78
B27: ='Ex 10 Projections'!B14 -> Selling, general, and administrative expenses | D27: ='Ex 10 Projections'!D14 -> 2179.31 | E27: ='Ex 10 Projections'!E14 -> 2189.6 | F27: ='Ex 10 Projections'!F14 -> 2223.7 | G27: ='Ex 10 Projections'!G14 -> 2395.05 | H27: ='Ex 10 Projections'!H14 -> 2313.43 | I27: ='Ex 10 Projections'!I14 -> 2443.78
B28: ='Ex 10 Projections'!B17 -> Depreciation and amortization | D28: ='Ex 10 Projections'!D17 -> 214.2 | E28: ='Ex 10 Projections'!E17 -> 224.83 | F28: ='Ex 10 Projections'!F17 -> 233.48 | G28: ='Ex 10 Projections'!G17 -> 250.75 | H28: ='Ex 10 Projections'!H17 -> 252.51 | I28: ='Ex 10 Projections'!I17 -> 263.87
B29: ='Ex 10 Projections'!B18 -> EBITDA | D29: =(D26-D27+D28) -> 1712.63 | E29: =(E26-E27+E28) -> 1438.43 | F29: =(F26-F27+F28) -> 1480.68 | G29: =(G26-G27+G28) -> 1476.83 | H29: =(H26-H27+H28) -> 1712.61 | I29: =(I26-I27+I28) -> 1796.87
B30: Haircut to EBITDA (difference from expected EBITDA vs. realitstic) | C30: 0 | D30: =D29*(1+$C$30) -> 1712.63 | E30: =E29*(1+$C$30) -> 1438.43 | F30: =F29*(1+$C$30) -> 1480.68 | G30: =G29*(1+$C$30) -> 1476.83 | H30: =H29*(1+$C$30) -> 1712.61 | I30: =I29*(1+$C$30) -> 1796.87
B32: ='Ex 10 Projections'!B15 -> Operating income (EBIT) | D32: =D30-D28 -> 1498.43 | E32: =E30-E28 -> 1213.6 | F32: =F30-F28 -> 1247.2 | G32: =G30-G28 -> 1226.08 | H32: =H30-H28 -> 1460.1 | I32: =I30-I28 -> 1533
B33: ='Ex 10 Projections'!B22 -> CAPEX | D33: ='Ex 10 Projections'!D22 -> 354.1 | E33: ='Ex 10 Projections'!E22 -> 249.4 | F33: ='Ex 10 Projections'!F22 -> 262.31 | G33: ='Ex 10 Projections'!G22 -> 263.81 | H33: ='Ex 10 Projections'!H22 -> 320.49 | I33: ='Ex 10 Projections'!I22 -> 345.07
B34: ='Ex 10 Projections'!B23 -> Change in net working capital (NWC) | D34: ='Ex 10 Projections'!D23 -> -152.6 | E34: ='Ex 10 Projections'!E23 -> 227.87 | F34: ='Ex 10 Projections'!F23 -> 6.07 | G34: ='Ex 10 Projections'!G23 -> 22.91 | H34: ='Ex 10 Projections'!H23 -> 23.63 | I34: ='Ex 10 Projections'!I23 -> 29.72
B36: FCF | E36: =E32*(1-$D$8)+E28-E33-E34 -> 682.032 | F36: =F32*(1-$D$8)+F28-F33-F34 -> 925.444 | G36: =G32*(1-$D$8)+G28-G33-G34 -> 908.1116 | H36: =H32*(1-$D$8)+H28-H33-H34 -> 1032.667 | I36: =I32*(1-$D$8)+I28-I33-I34 -> 1069.49
B37: Beginning Balance | E37: =E13 -> 5753.72 | F37: =E37-E38 -> 5466.034 | G37: =F37-F38 -> 5178.348 | H37: =G37-G38 -> 4890.662 | I37: =H37-H38 -> 4602.976
B38: Team A FCC (4x, 3x, 2x) Principal | E38: =$J$16*$E$37 -> 287.686 | F38: =$J$16*$E$37 -> 287.686 | G38: =$J$16*$E$37 -> 287.686 | H38: =$J$16*$E$37 -> 287.686 | I38: =$J$16*$E$37 -> 287.686
B39: Interest | E39: =$F$13*E37 -> 316.4546 | F39: =$F$13*F37 -> 300.63187 | G39: =$F$13*G37 -> 284.80914 | H39: =$F$13*H37 -> 268.98641 | I39: =$F$13*I37 -> 253.16368
B41: Total Debt | E41: =E38+E39 -> 604.1406 | F41: =F38+F39 -> 588.31787 | G41: =G38+G39 -> 572.49514 | H41: =H38+H39 -> 556.67241 | I41: =I38+I39 -> 540.84968
B42: Tax shield | E42: =E39*$D$8 -> 72.784558 | F42: =F39*$D$8 -> 69.14533 | G42: =G39*$D$8 -> 65.506102 | H42: =H39*$D$8 -> 61.866874 | I42: =I39*$D$8 -> 58.227646
B43: Excess Cash Flow | E43: =E36-E41+E42 -> 150.67596 | F43: =F36-F41+F42 -> 406.27146 | G43: =G36-G41+G42 -> 401.12256 | H43: =H36-H41+H42 -> 537.86146 | I43: =I36-I41+I42 -> 586.86797
B44: FCC | E44: =(E41+E43)/E41 -> 1.2494054 | F44: =(F41+F43)/F41 -> 1.6905645 | G44: =(G41+G43)/G41 -> 1.7006567 | H44: =(H41+H43)/H41 -> 1.9662082 | I44: =(I41+I43)/I41 -> 2.0850852
B46: Term B
B47: FCF | E47: =E43 -> 150.67596 | F47: =F43 -> 406.27146 | G47: =G43 -> 401.12256 | H47: =H43 -> 537.86146 | I47: =I43 -> 586.86797
B48: No principal
...

Sheet LBO Model- 3x Debt A
A1: Luke Buddie, Gennaro Di Mauro, Peter Spira, Caden Carney
B3: Step 1: Outline everything you know
B4: Williams-Sonoma, Inc., LBO: Let’s Get Cooking
B5: Assumptions
B7: 2024 EBITDA | D7: ='Ex 10 Projections'!E18 -> 1438.43 | E7: Exhibit 10 | H7: Exit multiple | I7: =D13 -> 8
B8: SOFR | D8: 0.03 | H8: Number of shares outstanding (in millions) | I8: ='Ex 11 Comps'!I16 -> 64.2 | J8: Exhibit 11
B9: Tax rate | D9: 0.23 | E9: Exhibit 10 | H9: Current enterprise value | I9: =('Ex 11 Comps'!I16*'Ex 11 Comps'!J16)+'Ex 11 Comps'!K16 -> 8758.648 | J9: Equity Value + Debt Value
B10: Opening Balance Cash | D10: 0 | E10: Exhibit 9 - Case
B12: Financing Package | E12: Amount | F12: Cash Interest | G12: PIK | J12: SOFR +
B13: Purchase multiple | D13: =SUM(D14:D17) -> 8 | E13: =D7*D13 -> 11507.44
B14: Term A | D14: 3 | E14: =D14*$D$7 -> 4315.29 | F14: =D8+J14 -> 0.055 | J14: 0.025
B15: Term B | D15: 1 | E15: =D15*$D$7 -> 1438.43 | F15: =D8+J15 -> 0.075 | J15: 0.045
B16: Mezzanine (Cavalier Capital) | D16: 2 | E16: =D16*$D$7 -> 2876.86 | F16: 0.11 | G16: 0.02 | J16: Minimum Priciple
B17: Equity investment (Jeffereson Capital Management) | D17: 2 | E17: =E13-E14-E15-E16 -> 2876.86 | J17: 0.05
B20: Step 2: How/Who are you going to pay down your debt with your free cash flow?
B21: Williams-Sonoma, Inc., LBO: Let’s Get Cooking
B22: Debt-Repayment Schedule | K22: Target Leverage
K23: Debt/EBITDA: 4-6x
D24: 2023 | E24: 2024 | F24: 2025 | G24: 2026 | H24: 2027 | I24: 2028
B25: ='Ex 10 Projections'!B11 -> Total revenue | D25: ='Ex 10 Projections'!D11 -> 8674.42 | E25: ='Ex 10 Projections'!E11 -> 8471 | F25: ='Ex 10 Projections'!F11 -> 8553 | G25: ='Ex 10 Projections'!G11 -> 8862.29 | H25: ='Ex 10 Projections'!H11 -> 9181.33 | I25: ='Ex 10 Projections'!I11 -> 9582.61
B26: ='Ex 10 Projections'!B12 -> Cost of goods sold | D26: ='Ex 10 Projections'!D12 -> 4996.68 | E26: ='Ex 10 Projections'!E12 -> 5067.8 | F26: ='Ex 10 Projections'!F12 -> 5082.1 | G26: ='Ex 10 Projections'!G12 -> 5241.16 | H26: ='Ex 10 Projections'!H12 -> 5407.8 | I26: ='Ex 10 Projections'!I12 -> 5605.83
B27: ='Ex 10 Projections'!B13 -> Gross profit | D27: =D25-D26 -> 3677.74 | E27: =E25-E26 -> 3403.2 | F27: =F25-F26 -> 3470.9 | G27: =G25-G26 -> 3621.13 | H27: =H25-H26 -> 3773.53 | I27: =I25-I26 -> 3976.78
B28: ='Ex 10 Projections'!B14 -> Selling, general, and administrative expenses | D28: ='Ex 10 Projections'!D14 -> 2179.31 | E28: ='Ex 10 Projections'!E14 -> 2189.6 | F28: ='Ex 10 Projections'!F14 -> 2223.7 | G28: ='Ex 10 Projections'!G14 -> 2395.05 | H28: ='Ex 10 Projections'!H14 -> 2313.43 | I28: ='Ex 10 Projections'!I14 -> 2443.78
B29: ='Ex 10 Projections'!B17 -> Depreciation and amortization | D29: ='Ex 10 Projections'!D17 -> 214.2 | E29: ='Ex 10 Projections'!E17 -> 224.83 | F29: ='Ex 10 Projections'!F17 -> 233.48 | G29: ='Ex 10 Projections'!G17 -> 250.75 | H29: ='Ex 10 Projections'!H17 -> 252.51 | I29: ='Ex 10 Projections'!I17 -> 263.87
B30: ='Ex 10 Projections'!B18 -> EBITDA | D30: =(D27-D28+D29) -> 1712.63 | E30: =(E27-E28+E29) -> 1438.43 | F30: =(F27-F28+F29) -> 1480.68 | G30: =(G27-G28+G29) -> 1476.83 | H30: =(H27-H28+H29) -> 1712.61 | I30: =(I27-I28+I29) -> 1796.87
B31: Haircut to EBITDA (difference from expected EBITDA vs. realitstic) | C31: 0 | D31: =D30*(1+$C$31) -> 1712.63 | E31: =E30*(1+$C$31) -> 1438.43 | F31: =F30*(1+$C$31) -> 1480.68 | G31: =G30*(1+$C$31) -> 1476.83 | H31: =H30*(1+$C$31) -> 1712.61 | I31: =I30*(1+$C$31) -> 1796.87
B33: ='Ex 10 Projections'!B15 -> Operating income (EBIT) | D33: =D31-D29 -> 1498.43 | E33: =E31-E29 -> 1213.6 | F33: =F31-F29 -> 1247.2 | G33: =G31-G29 -> 1226.08 | H33: =H31-H29 -> 1460.1 | I33: =I31-I29 -> 1533
B34: ='Ex 10 Projections'!B22 -> CAPEX | D34: ='Ex 10 Projections'!D22 -> 354.1 | E34: ='Ex 10 Projections'!E22 -> 249.4 | F34: ='Ex 10 Projections'!F22 -> 262.31 | G34: ='Ex 10 Projections'!G22 -> 263.81 | H34: ='Ex 10 Projections'!H22 -> 320.49 | I34: ='Ex 10 Projections'!I22 -> 345.07
B35: ='Ex 10 Projections'!B23 -> Change in net working capital (NWC) | D35: ='Ex 10 Projections'!D23 -> -152.6 | E35: ='Ex 10 Projections'!E23 -> 227.87 | F35: ='Ex 10 Projections'!F23 -> 6.07 | G35: ='Ex 10 Projections'!G23 -> 22.91 | H35: ='Ex 10 Projections'!H23 -> 23.63 | I35: ='Ex 10 Projections'!I23 -> 29.72
B37: FCF | E37: =E33*(1-$D$9)+E29-E34-E35 -> 682.032 | F37: =F33*(1-$D$9)+F29-F34-F35 -> 925.444 | G37: =G33*(1-$D$9)+G29-G34-G35 -> 908.1116 | H37: =H33*(1-$D$9)+H29-H34-H35 -> 1032.667 | I37: =I33*(1-$D$9)+I29-I34-I35 -> 1069.49
B38: Beginning Balance | E38: =E14 -> 4315.29 | F38: =E38-E39 -> 4099.5255 | G38: =F38-F39 -> 3883.761 | H38: =G38-G39 -> 3667.9965 | I38: =H38-H39 -> 3452.232
B39: Team A FCC (4x, 3x, 2x) Principal | E39: =$J$17*$E$38 -> 215.7645 | F39: =$J$17*$E$38 -> 215.7645 | G39: =$J$17*$E$38 -> 215.7645 | H39: =$J$17*$E$38 -> 215.7645 | I39: =$J$17*$E$38 -> 215.7645
B40: Interest | E40: =$F$14*E38 -> 237.34095 | F40: =$F$14*F38 -> 225.4739 | G40: =$F$14*G38 -> 213.60685 | H40: =$F$14*H38 -> 201.73981 | I40: =$F$14*I38 -> 189.87276
B42: Total Debt | E42: =E39+E40 -> 453.10545 | F42: =F39+F40 -> 441.2384 | G42: =G39+G40 -> 429.37135 | H42: =H39+H40 -> 417.50431 | I42: =I39+I40 -> 405.63726
B43: Tax shield | E43: =E40*$D$9 -> 54.588419 | F43: =F40*$D$9 -> 51.858998 | G43: =G40*$D$9 -> 49.129577 | H43: =H40*$D$9 -> 46.400156 | I43: =I40*$D$9 -> 43.670735
B44: Excess Cash Flow | E44: =E37-E42+E43 -> 283.51497 | F44: =F37-F42+F43 -> 536.0646 | G44: =G37-G42+G43 -> 527.86982 | H44: =H37-H42+H43 -> 661.56285 | I44: =I37-I42+I43 -> 707.52347
B45: FCC | E45: =(E42+E44)/E42 -> 1.6257152 | F45: =(F42+F44)/F42 -> 2.2149092 | G45: =(G42+G44)/G42 -> 2.2294016 | H45: =(H42+H44)/H42 -> 2.5845653 | I45: =(I42+I44)/I42 -> 2.744227
B47: Term B
B48: FCF | E48: =E44 -> 283.51497 | F48: =F44 -> 536.0646 | G48: =G44 -> 527.86982 | H48: =H44 -> 661.56285 | I48: =I44 -> 707.52347
B49: No principal
...

Sheet Hayden Notes
B3: Financing Package is based on Case information
B6: Hayden's Free Cash Flows
B7: 2024 | C7: 682.032
B8: 2025 | C8: 925.444
B9: 2026 | C9: 908.1116
B10: 2027 | C10: 1032.667
B11: 2028 | C11: 1069.49
B13: Cash Interest is outlined in the case. It's SOFR + Something
B14: BPS = Basis Points. 100 bps = 1.00%
B15: SOFR = Secured Overnight Financing Rate.
B16: PIK = paid in kind.
B17: EBIT = earnings before interest and taxes.
B18: CAPEX = capital expenditure.

Sheet Ex 10 Projections
B1: Exhibit 10
B2: Williams-Sonoma, Inc., LBO: Let’s Get Cooking
B3: Williams-Sonoma: Financial Forecast
B5: Fiscal period ending January (in millions of US dollars) | C5: 44592 | D5: 44957 | E5: 45322 | F5: 45688 | G5: 46053 | H5: 46418 | I5: 46783
B6: Pottery Barn | C6: 3120.69 | D6: 3555.52 | E6: 3469 | F6: 3414 | G6: 3537.46 | H6: 3664.8 | I6: 3824.98
B7: West Elm | C7: 2234.55 | D7: 2278.13 | E7: 2277 | F7: 2454 | G7: 2542.74 | H7: 2634.28 | I7: 2749.41
B8: Williams Sonoma | C8: 1345.85 | D8: 1286.65 | E8: 1244 | F8: 1224 | G8: 1268.26 | H8: 1313.92 | I8: 1371.35
B9: Pottery Barn Kids and Teen | C9: 1139.89 | D9: 1132.94 | E9: 1052 | F9: 998 | G9: 1034.09 | H9: 1071.32 | I9: 1118.14
B10: Other | C10: 404.96 | D10: 421.18 | E10: 429 | F10: 463 | G10: 479.74 | H10: 497.01 | I10: 518.74
B11: Total revenue | C11: 8245.94 | D11: 8674.42 | E11: 8471 | F11: 8553 | G11: 8862.29 | H11: 9181.33 | I11: 9582.61
B12: Cost of goods sold | C12: 4613.97 | D12: 4996.68 | E12: 5067.8 | F12: 5082.1 | G12: 5241.16 | H12: 5407.8 | I12: 5605.83
B13: Gross profit | C13: 3631.96 | D13: 3677.73 | E13: 3403.2 | F13: 3470.9 | G13: 3621.13 | H13: 3773.53 | I13: 3976.78
B14: Selling, general, and administrative expenses | C14: 2178.85 | D14: 2179.31 | E14: 2189.6 | F14: 2223.7 | G14: 2395.05 | H14: 2313.43 | I14: 2443.78
B15: Operating income (EBIT) | C15: 1453.12 | D15: 1498.42 | E15: 1213.6 | F15: 1247.2 | G15: 1226.08 | H15: 1460.1 | I15: 1533
B17: Depreciation and amortization | C17: 196.1 | D17: 214.2 | E17: 224.83 | F17: 233.48 | G17: 250.75 | H17: 252.51 | I17: 263.87
... B23: Change in net working capital (NWC) | C23: -366.3 | D23: -152.6 | E23: 227.87 | F23: 6.07 | G23: 22.91 | H23: 23.63 | I23: 29.72
B26: ¹ Tax rate is 23%.
B27: Note: Data is for 12 months ending January 31 of each year.
B28: EBIT = earnings before interest and taxes.
B29: NOPAT = net operating profit after tax.
B30: CAPEX = capital expenditure.
B32: Data source: Capital IQ and analyst estimates.

Sheet Ex 11 Comps
B1: Exhibit 11
B2: Williams-Sonoma, Inc., LBO: Let’s Get Cooking
B3: Comparable Companies Analysis
B5: Company Name | C5: Sales | D5: EBITDA | E5: EBIT | F5: Year-over-Year (YoY) Sales Growth | G5: YoY EBITDA Growth | H5: YoY EBIT Growth | I5: Number of Shares | J5: Price per Share | K5: Debt | L5: Cash | M5: Beta | N5: Enterprise Value/ EBITDA | O5: Debt/EBITDA
B6: RH (NYSE:RH) | C6: 3590.5 | D6: 839.7 | E6: 731.2 | F6: -0.044774928 | G6: -0.18736088 | H6: -0.21988691 | I6: 22.1 | J6: 244.64 | K6: 3749.5 | L6: 1508.1 | M6: 2.08 | N6: =(I6*J6+K6-L6)/D6 -> 9.1079481 | O6: =K6/D6 -> 4.4652852
B7: Sleep Number Corporation (NasdaqGS:SNBR) | C7: 2114.3 | D7: 133.3 | E7: 67.9 | F7: -0.032312692 | G7: -0.47082175 | H7: -0.64909561 | I7: 22.2 | J7: 18.1 | K7: 896 | L7: 1.79 | M7: 1.83 | N7: =(I7*J7+K7-L7)/D7 -> 9.7226557 | O7: =K7/D7 -> 6.7216804
B8: Lowe’s Companies, Inc. (NYSE:LOW) | C8: 97059 | D8: 14201 | E8: 12220 | F8: 0.0084051948 | G8: 0.016171735 | H8: 0.010501943 | I8: 592 | J8: 203.92 | K8: 38082 | L8: 1983 | M8: 1.07 | N8: =(I8*J8+K8-L8)/D8 -> 11.042859 | O8: =K8/D8 -> 2.6816421 | P8: =AVERAGE(O6:O14) -> 1.2888821 | Q8: AVG
B9: The Home Depot, Inc. (NYSE:HD) | C9: 157403 | D9: 27014 | E9: 24039 | F9: 0.041321275 | G9: 0.042931048 | H9: 0.043359375 | I9: 1005.4 | J9: 288.39 | K9: 50364 | L9: 2757 | M9: 0.93 | N9: =(I9*J9+K9-L9)/D9 -> 12.495532 | O9: =K9/D9 -> 1.8643666
B10: Bed Bath & Beyond Inc. (OTCPK:BBBY.Q) | C10: 6210.9 | D10: -612.7 | E10: -922.6 | F10: -0.26371881 | G10: -2.6234764 | H10: -11.944247 | I10: 466 | J10: 0.26 | K10: 3698.7 | L10: 153.52 | M10: 1.45 | O10: =K10/D10 -> -6.0367227
B11: Tractor Supply Company (NasdaqGS:TSCO) | C11: 14204.7 | D11: 1778 | E11: 1434.9 | F11: 0.11574805 | G11: 0.1275287 | H11: 0.098109742 | I11: 109.6 | J11: 206.32 | K11: 4270.2 | L11: 202.5 | M11: 0.82 | N11: =(I11*J11+K11-L11)/D11 -> 15.005834 | O11: =K11/D11 -> 2.4016873
B12: Overstock.com, Inc. (NasdaqGM:OSTK) | C12: 1929.3 | D12: 37.1 | E12: 27 | F12: -0.3000653 | G12: -0.69689542 | H12: -0.7569757 | I12: 45.2 | J12: 18.81 | K12: 46 | L12: 371.26 | M12: 3.37 | N12: =(I12*J12+K12-L12)/D12 -> 14.14965 | O12: =K12/D12 -> 1.2398922
B13: Wayfair Inc. (NYSE:W) | C13: 12218 | D13: -1167 | E13: -1314 | F13: -0.10869565 | G13: -17.913043 | H13: 15.02439 | I13: 112.3 | J13: 43.01 | K13: 4155 | L13: 1278 | M13: 3.01 | O13: =K13/D13 -> -3.5604113
B14: Arhaus, Inc. (NasdaqGS:ARHS) | C14: 1228.9 | D14: 209.6 | E14: 184.7 | F14: 0.54210064 | G14: 2.1097923 | H14: 3.245977 | I14: 140 | J14: 6.81 | K14: 382 | L14: 145.18 | M14: NA | N14: =(I14*J14+K14-L14)/D14 -> 5.6785305 | O14: =K14/D14 -> 1.8225191
B16: Williams-Sonoma, Inc. (NYSE:WSM) | C16: 8674.4 | D16: 1728.2 | E16: 1514 | F16: 0.051965219 | G16: 0.047902013 | H16: 0.041910398 | I16: 64.2 | J16: 113.94 | K16: 1443.7 | L16: 367.34 | M16: 1.59 | N16: =(I16*J16+K16)/D16 -> 5.0680755
B18: Financial data as of December 31, 2022; market data as of June 1, 2023.
B19: Beta is calculated using five-year historical data.
B20: All financials have been adjusted to represent 12-month calendar year financials based on respective fiscal year ends.
B22: Data source: Capital IQ.
